CRITICAL:root:**** TEMPORARY ADMIN PASSWORD: zaKo0hD9joz0HtLmZv1SLw ****
CRITICAL:root:**** CHANGE THIS PASSWORD IMMEDIATELY ****
/Users/mikelsmart/Downloads/GitHubProjects/MotionEye-Custom/motioneye_env/lib/python3.13/site-packages/face_recognition_models/__init__.py:7: UserWarning: pkg_resources is deprecated as an API. See https://setuptools.pypa.io/en/latest/pkg_resources.html. The pkg_resources package is slated for removal as early as 2025-11-30. Refrain from using this package or pin to Setuptools<81.
  from pkg_resources import resource_filename
configure_logging cmd motioneye: False
configure logging to file: None
    INFO: uvloop not available, using default asyncio
    INFO: File descriptor limit increased to 4096
    INFO: hello! this is motionEye server 0.43.1b4
    INFO: motion not installed
    INFO: v4l-utils not installed
    INFO: Successfully connected to database at ./conf/motioneye.db
    INFO: Database initialized successfully.
 WARNING: Could not create index, this may be normal on first run: no such table: main.events
 WARNING: Could not create index, this may be normal on first run: no such table: main.events
 WARNING: Could not create index, this may be normal on first run: no such table: main.events
 WARNING: Could not create index, this may be normal on first run: no such table: main.media_files
 WARNING: Could not create index, this may be normal on first run: no such table: main.media_files
    INFO: Database indexes created successfully
   ERROR: motion executable could not be found
Traceback (most recent call last):
  File "/Users/mikelsmart/Downloads/GitHubProjects/MotionEye-Custom/motioneye/server.py", line 395, in start_motion
    motionctl.start()
    ~~~~~~~~~~~~~~~^^
  File "/Users/mikelsmart/Downloads/GitHubProjects/MotionEye-Custom/motioneye/motionctl.py", line 98, in start
    raise Exception('motion executable could not be found')
Exception: motion executable could not be found
    INFO: Motion daemon monitoring started
    INFO: cleanup started
    INFO: wsswitch started
Traceback (most recent call last):
  File "<frozen runpy>", line 198, in _run_module_as_main
  File "<frozen runpy>", line 88, in _run_code
  File "/Users/mikelsmart/Downloads/GitHubProjects/MotionEye-Custom/motioneye/meyectl.py", line 442, in <module>
    main()
    ~~~~^^
  File "/Users/mikelsmart/Downloads/GitHubProjects/MotionEye-Custom/motioneye/meyectl.py", line 411, in main
    server.main(arg_parser, sys.argv[2:], command[:-6])
    ~~~~~~~~~~~^^^^^^^^^^^^^^^^^^^^^^^^^^^^^^^^^^^^^^^^
  File "/Users/mikelsmart/Downloads/GitHubProjects/MotionEye-Custom/motioneye/server.py", line 595, in main
    run()
    ~~~^^
   ERROR: Motion daemon not running!
  File "/Users/mikelsmart/Downloads/GitHubProjects/MotionEye-Custom/motioneye/server.py", line 528, in run
    tasks.start()
    ~~~~~~~~~~~^^
  File "/Users/mikelsmart/Downloads/GitHubProjects/MotionEye-Custom/motioneye/tasks.py", line 80, in start
    _pool = multiprocessing.Pool(_POOL_SIZE, initializer=init_pool_process)
  File "/Library/Frameworks/Python.framework/Versions/3.13/lib/python3.13/multiprocessing/context.py", line 119, in Pool
    return Pool(processes, initializer, initargs, maxtasksperchild,
                context=self.get_context())
    INFO: Attempting to restart Motion (attempt 1)
  File "/Library/Frameworks/Python.framework/Versions/3.13/lib/python3.13/multiprocessing/pool.py", line 215, in __init__
    self._repopulate_pool()
    ~~~~~~~~~~~~~~~~~~~~~^^
  File "/Library/Frameworks/Python.framework/Versions/3.13/lib/python3.13/multiprocessing/pool.py", line 306, in _repopulate_pool
    return self._repopulate_pool_static(self._ctx, self.Process,
           ~~~~~~~~~~~~~~~~~~~~~~~~~~~~^^^^^^^^^^^^^^^^^^^^^^^^^
                                        self._processes,
                                        ^^^^^^^^^^^^^^^^
    ...<3 lines>...
                                        self._maxtasksperchild,
                                        ^^^^^^^^^^^^^^^^^^^^^^^
                                        self._wrap_exception)
                                        ^^^^^^^^^^^^^^^^^^^^^
  File "/Library/Frameworks/Python.framework/Versions/3.13/lib/python3.13/multiprocessing/pool.py", line 329, in _repopulate_pool_static
    w.start()
    ~~~~~~~^^
  File "/Library/Frameworks/Python.framework/Versions/3.13/lib/python3.13/multiprocessing/process.py", line 121, in start
    self._popen = self._Popen(self)
                  ~~~~~~~~~~~^^^^^^
  File "/Library/Frameworks/Python.framework/Versions/3.13/lib/python3.13/multiprocessing/context.py", line 289, in _Popen
    return Popen(process_obj)
  File "/Library/Frameworks/Python.framework/Versions/3.13/lib/python3.13/multiprocessing/popen_spawn_posix.py", line 32, in __init__
    super().__init__(process_obj)
    ~~~~~~~~~~~~~~~~^^^^^^^^^^^^^
  File "/Library/Frameworks/Python.framework/Versions/3.13/lib/python3.13/multiprocessing/popen_fork.py", line 20, in __init__
    self._launch(process_obj)
    ~~~~~~~~~~~~^^^^^^^^^^^^^
  File "/Library/Frameworks/Python.framework/Versions/3.13/lib/python3.13/multiprocessing/popen_spawn_posix.py", line 47, in _launch
    reduction.dump(process_obj, fp)
    ~~~~~~~~~~~~~~^^^^^^^^^^^^^^^^^
  File "/Library/Frameworks/Python.framework/Versions/3.13/lib/python3.13/multiprocessing/reduction.py", line 60, in dump
    ForkingPickler(file, protocol).dump(obj)
    ~~~~~~~~~~~~~~~~~~~~~~~~~~~~~~~~~~~^^^^^
AttributeError: Can't get local object 'start.<locals>.init_pool_process'
Could not find service "org.motion.motiond" in domain for system
